<?xml version="1.0" ?>
<!-- Generated using onshape-to-robot -->
<!-- Onshape https://cad.onshape.com/documents/d6f28038394c6695a0af51fb/w/e48a2577644550901c42c5dc/e/c11f9da44c24d4a76c2e0eb3 -->
<mujoco model="biped">
  <compiler angle="radian" meshdir="assets" autolimits="true"/>
  <option gravity="0 0 -9.81"/>
  <default>
    <default class="biped">
      <joint frictionloss="0.1" armature="0.005"/>
      <position kp="50" dampratio="1"/>
      <default class="visual">
        <geom type="mesh" contype="0" conaffinity="0" group="2"/>
      </default>
      <default class="collision">
      </default>
    </default>
  </default>
  <worldbody>
    <!-- Link body -->
    <body name="body" pos="0 0 0.07" quat="1 0 0 0" childclass="biped">
      <freejoint/>
      <inertial pos="0.0059619 0.00494356 0.00225219" mass="0.0554646" fullinertia="1.79281e-05 1.2609e-05 2.84293e-05 0 0 0"/>
      <!-- Part body -->
      <geom type="mesh" class="visual" pos="0.0059619 0.00494356 -0.00524781" quat="1 0 0 0" mesh="body" material="body_material"/>
      <geom type="mesh" class="collision" pos="0.0059619 0.00494356 -0.00524781" quat="1 0 0 0" mesh="body" material="body_material"/>
      <!-- Link femur -->
      <body name="femur" pos="0.0309619 0.00494356 0.00225219" quat="0.5 -0.5 -0.5 0.5">
        <!-- Joint from body to femur -->
        <joint axis="0 0 1" name="femur_1" type="hinge" range="-1.5707963267948966 1.5707963267948966"/>
        <inertial pos="3.07605e-18 0.0125 -0.003" mass="0.0024365" fullinertia="2.45637e-07 2.8996e-08 2.60014e-07 0 0 -3.26676e-52"/>
        <!-- Part femur -->
        <geom type="mesh" class="visual" pos="3.42538e-19 0.06 -0.017" quat="0.707107 0.707107 -0 -0" mesh="femur" material="femur_material"/>
        <geom type="mesh" class="collision" pos="3.42538e-19 0.06 -0.017" quat="0.707107 0.707107 -0 -0" mesh="femur" material="femur_material"/>
        <!-- Link tibia -->
        <body name="tibia" pos="1.67249e-18 0.025 -0.006" quat="1 0 0 0">
          <!-- Joint from femur to tibia -->
          <joint axis="0 0 1" name="tibia_1" type="hinge" range="-1.5707963267948966 1.5707963267948966"/>
          <inertial pos="1.94726e-18 0.0175 -0.003" mass="0.0031865" fullinertia="5.21176e-07 3.7496e-08 5.39552e-07 0 0 0"/>
          <!-- Part tibia -->
          <geom type="mesh" class="visual" pos="3.42538e-19 0.035 -0.011" quat="0.707107 0.707107 -0 -0" mesh="tibia" material="tibia_material"/>
          <geom type="mesh" class="collision" pos="3.42538e-19 0.035 -0.011" quat="0.707107 0.707107 -0 -0" mesh="tibia" material="tibia_material"/>
          <!-- Link wheel -->
          <body name="wheel" pos="6.31659e-19 0.035 -0.006" quat="1 0 0 0">
            <!-- Joint from tibia to wheel -->
            <joint axis="0 0 1" name="wheel_1" type="hinge" limited="false"/>
            <inertial pos="-5.15292e-19 -1.22984e-18 -0.005" mass="0.00867865" fullinertia="5.69175e-07 5.69175e-07 9.93705e-07 0 0 0"/>
            <!-- Part wheel -->
            <geom type="mesh" class="visual" pos="-5.24823e-19 0 -0.005" quat="0.707107 0.707107 -0 -0" mesh="wheel" material="wheel_material"/>
            <geom type="mesh" class="collision" pos="-5.24823e-19 0 -0.005" quat="0.707107 0.707107 -0 -0" mesh="wheel" material="wheel_material"/>
          </body>
        </body>
      </body>
      <!-- Link femur_2 -->
      <body name="femur_2" pos="-0.0190381 0.00494356 0.00225219" quat="0.5 -0.5 0.5 -0.5">
        <!-- Joint from body to femur_2 -->
        <joint axis="0 0 1" name="femur_2" type="hinge" range="-1.5707963267948966 1.5707963267948966"/>
        <inertial pos="2.56445e-18 0.0125 -0.003" mass="0.0024365" fullinertia="2.45637e-07 2.8996e-08 2.60014e-07 0 0 0"/>
        <!-- Part femur_2 -->
        <geom type="mesh" class="visual" pos="-1.69066e-19 0.06 -0.017" quat="0.707107 0.707107 -0 -0" mesh="femur" material="femur_material"/>
        <geom type="mesh" class="collision" pos="-1.69066e-19 0.06 -0.017" quat="0.707107 0.707107 -0 -0" mesh="femur" material="femur_material"/>
        <!-- Link tibia_2 -->
        <body name="tibia_2" pos="2.93527e-19 0.025 -0.006" quat="1 0 0 0">
          <!-- Joint from femur_2 to tibia_2 -->
          <joint axis="0 0 1" name="tibia_2" type="hinge" range="-1.5707963267948966 1.5707963267948966"/>
          <inertial pos="2.30301e-18 0.0175 -0.003" mass="0.0031865" fullinertia="5.21176e-07 3.7496e-08 5.39552e-07 0 0 0"/>
          <!-- Part tibia_2 -->
          <geom type="mesh" class="visual" pos="6.98296e-19 0.035 -0.011" quat="0.707107 0.707107 -0 -0" mesh="tibia" material="tibia_material"/>
          <geom type="mesh" class="collision" pos="6.98296e-19 0.035 -0.011" quat="0.707107 0.707107 -0 -0" mesh="tibia" material="tibia_material"/>
          <!-- Link wheel_2 -->
          <body name="wheel_2" pos="1.85478e-18 0.035 -0.006" quat="0 0 0 1">
            <!-- Joint from tibia_2 to wheel_2 -->
            <joint axis="0 0 1" name="wheel_2" type="hinge" limited="false"/>
            <inertial pos="1.78597e-19 -1.22984e-18 -0.005" mass="0.00867865" fullinertia="5.69175e-07 5.69175e-07 9.93705e-07 0 0 0"/>
            <!-- Part wheel_2 -->
            <geom type="mesh" class="visual" pos="1.69066e-19 0 -0.005" quat="0.707107 0.707107 -0 -0" mesh="wheel" material="wheel_material"/>
            <geom type="mesh" class="collision" pos="1.69066e-19 0 -0.005" quat="0.707107 0.707107 -0 -0" mesh="wheel" material="wheel_material"/>
          </body>
        </body>
      </body>
    </body>
  </worldbody>
  <asset>
    <mesh file="tibia.stl"/>
    <mesh file="wheel.stl"/>
    <mesh file="body.stl"/>
    <mesh file="femur.stl"/>
    <material name="body_material" rgba="1 0 0 1"/>
    <material name="femur_material" rgba="0.701961 0.701961 0.701961 1"/>
    <material name="tibia_material" rgba="0.917647 0.917647 0.917647 1"/>
    <material name="wheel_material" rgba="0 0 0 1"/>
  </asset>
  <actuator>
    <position class="biped" name="femur_1" joint="femur_1" inheritrange="1"/>
    <position class="biped" name="tibia_1" joint="tibia_1" inheritrange="1"/>
    <velocity name="wheel_1" joint="wheel_1" kv="1.0"/>
    <position class="biped" name="femur_2" joint="femur_2" inheritrange="1"/>
    <position class="biped" name="tibia_2" joint="tibia_2" inheritrange="1"/>
    <velocity name="wheel_2" joint="wheel_2" kv="1.0"/>
  </actuator>
  <equality/>
</mujoco>
