<?xml version="1.0" ?>
<!-- Generated using onshape-to-robot -->
<!-- Onshape https://cad.onshape.com/documents/d6f28038394c6695a0af51fb/w/e48a2577644550901c42c5dc/e/c11f9da44c24d4a76c2e0eb3 -->
<mujoco model="biped2">
  <compiler angle="radian" meshdir="assets" autolimits="true"/>
  <default>
    <default class="biped2">
      <joint frictionloss="0.1" armature="0.005"/>
      <position kp="50" dampratio="1"/>
      <default class="visual">
        <geom type="mesh" contype="0" conaffinity="0" group="2"/>
      </default>
      <default class="collision">
        <geom group="3"/>
      </default>
    </default>
  </default>
  <worldbody>
    <!-- Link body -->
    <body name="body" pos="0 0 0.1" quat="1 0 0 0" childclass="biped2">
      <freejoint name="body_freejoint"/>
      <inertial pos="0.00628116 0.014969 0.011239" mass="0.000443717" fullinertia="1.43425e-07 1.00872e-07 2.27435e-07 0 0 0"/>
      <!-- Part body -->
      <geom type="mesh" class="visual" pos="0.00628116 0.014969 0.00373902" quat="1 0 0 0" mesh="body" material="body_material"/>
      <geom type="mesh" class="collision" pos="0.00628116 0.014969 0.00373902" quat="1 0 0 0" mesh="body" material="body_material"/>
      <!-- Link femur -->
      <body name="femur" pos="0.0312812 0.014969 0.011239" quat="0.5 -0.5 -0.5 0.5">
        <!-- Joint from body to femur -->
        <joint axis="0 0 1" name="femur_1" type="hinge" range="-1.5707963267948966 1.5707963267948966"/>
        <inertial pos="3.11297e-18 0.0125 -0.003" mass="0.0024365" fullinertia="2.45637e-07 2.8996e-08 2.60014e-07 0 0 -3.26676e-52"/>
        <!-- Part femur -->
        <geom type="mesh" class="visual" pos="3.79461e-19 0.06 -0.017" quat="0.707107 0.707107 -0 -0" mesh="femur" material="femur_material"/>
        <geom type="mesh" class="collision" pos="3.79461e-19 0.06 -0.017" quat="0.707107 0.707107 -0 -0" mesh="femur" material="femur_material"/>
        <!-- Link tibia -->
        <body name="tibia" pos="8.42053e-19 0.025 -0.006" quat="1 0 0 0">
          <!-- Joint from femur to tibia -->
          <joint axis="0 0 1" name="tibia_1" type="hinge" range="-1.5707963267948966 1.5707963267948966"/>
          <inertial pos="1.98418e-18 0.0175 -0.003" mass="0.0031865" fullinertia="5.21176e-07 3.7496e-08 5.39552e-07 0 0 0"/>
          <!-- Part tibia -->
          <geom type="mesh" class="visual" pos="3.79461e-19 0.035 -0.011" quat="0.707107 0.707107 -0 -0" mesh="tibia" material="tibia_material"/>
          <geom type="mesh" class="collision" pos="3.79461e-19 0.035 -0.011" quat="0.707107 0.707107 -0 -0" mesh="tibia" material="tibia_material"/>
          <!-- Link wheel -->
          <body name="wheel" pos="-1.98781e-19 0.035 -0.006" quat="1 0 0 0">
            <!-- Joint from tibia to wheel -->
            <joint axis="0 0 1" name="wheel_1"/>
            <inertial pos="3.88992e-19 -1.22984e-18 -0.005" mass="0.0545019" fullinertia="3.57442e-06 3.57442e-06 6.24047e-06 0 0 0"/>
            <!-- Part wheel -->
            <geom type="mesh" class="visual" pos="3.79461e-19 0 -0.005" quat="0.707107 0.707107 -0 -0" mesh="wheel" material="wheel_material"/>
            <geom type="mesh" class="collision" pos="3.79461e-19 0 -0.005" quat="0.707107 0.707107 -0 -0" mesh="wheel" material="wheel_material"/>
          </body>
        </body>
      </body>
      <!-- Link femur_2 -->
      <body name="femur_2" pos="-0.0187188 0.014969 0.011239" quat="0.5 -0.5 0.5 -0.5">
        <!-- Joint from body to femur_2 -->
        <joint axis="0 0 1" name="femur_2" type="hinge" range="-1.5707963267948966 1.5707963267948966"/>
        <inertial pos="3.39489e-18 0.0125 -0.003" mass="0.0024365" fullinertia="2.45637e-07 2.8996e-08 2.60014e-07 0 0 0"/>
        <!-- Part femur_2 -->
        <geom type="mesh" class="visual" pos="6.61374e-19 0.06 -0.017" quat="0.707107 0.707107 -0 -0" mesh="femur" material="femur_material"/>
        <geom type="mesh" class="collision" pos="6.61374e-19 0.06 -0.017" quat="0.707107 0.707107 -0 -0" mesh="femur" material="femur_material"/>
        <!-- Link tibia_2 -->
        <body name="tibia_2" pos="1.12397e-18 0.025 -0.006" quat="1 0 0 0">
          <!-- Joint from femur_2 to tibia_2 -->
          <joint axis="0 0 1" name="tibia_2" type="hinge" range="-1.5707963267948966 1.5707963267948966"/>
          <inertial pos="5.31367e-19 0.0175 -0.003" mass="0.0031865" fullinertia="5.21176e-07 3.7496e-08 5.39552e-07 0 0 0"/>
          <!-- Part tibia_2 -->
          <geom type="mesh" class="visual" pos="-1.07335e-18 0.035 -0.011" quat="0.707107 0.707107 -0 -0" mesh="tibia" material="tibia_material"/>
          <geom type="mesh" class="collision" pos="-1.07335e-18 0.035 -0.011" quat="0.707107 0.707107 -0 -0" mesh="tibia" material="tibia_material"/>
          <!-- Link wheel_2 -->
          <body name="wheel_2" pos="-1.65159e-18 0.035 -0.006" quat="0 0 0 1">
            <!-- Joint from tibia_2 to wheel_2 -->
            <joint axis="0 0 1" name="wheel_2"/>
            <inertial pos="-6.51842e-19 -1.22984e-18 -0.005" mass="0.0545019" fullinertia="3.57442e-06 3.57442e-06 6.24047e-06 0 0 0"/>
            <!-- Part wheel_2 -->
            <geom type="mesh" class="visual" pos="-6.61374e-19 0 -0.005" quat="0.707107 0.707107 -0 -0" mesh="wheel" material="wheel_material"/>
            <geom type="mesh" class="collision" pos="-6.61374e-19 0 -0.005" quat="0.707107 0.707107 -0 -0" mesh="wheel" material="wheel_material"/>
          </body>
        </body>
      </body>
    </body>
  </worldbody>
  <asset>
    <mesh file="wheel.stl"/>
    <mesh file="tibia.stl"/>
    <mesh file="femur.stl"/>
    <mesh file="body.stl"/>
    <material name="body_material" rgba="1 0 0 1"/>
    <material name="femur_material" rgba="0.701961 0.701961 0.701961 1"/>
    <material name="tibia_material" rgba="0.917647 0.917647 0.917647 1"/>
    <material name="wheel_material" rgba="0 0 0 1"/>
  </asset>
  <actuator>
    <position class="biped2" name="femur_1" joint="femur_1" inheritrange="1"/>
    <position class="biped2" name="tibia_1" joint="tibia_1" inheritrange="1"/>
    <position class="biped2" name="wheel_1" joint="wheel_1"/>
    <position class="biped2" name="femur_2" joint="femur_2" inheritrange="1"/>
    <position class="biped2" name="tibia_2" joint="tibia_2" inheritrange="1"/>
    <position class="biped2" name="wheel_2" joint="wheel_2"/>
  </actuator>
  <equality/>
</mujoco>
